<?xml version="1.0"?>
<robot name="robot" xmlns:xacro="http://ros.org/wiki/xacro">

  <xacro:macro name="material_light_black">
    <visual>
      <material>
        <diffuse>0.1 0.1 0.1 1</diffuse>
        <specular>0.1 0.1 0.1 1</specular>
        <emissive>0 0 0 1</emissive>
      </material>
    </visual>
  </xacro:macro>

  <xacro:macro name="material_darkgray">
    <visual>
      <material>
        <diffuse>0.05 0.05 0.05 1</diffuse>
        <specular>0.05 0.05 0.05 1</specular>
        <emissive>0 0 0 1</emissive>
      </material>
    </visual>
  </xacro:macro>

  <gazebo reference="scan_link">
    <sensor type="gpu_lidar" name="head_laser">
      <update_rate>30</update_rate>
      <visualize>true</visualize>
      <topic>scan</topic>
      <lidar>
        <scan>
          <horizontal>
            <samples>360</samples>
            <resolution>1</resolution>
            <min_angle>-3.14159</min_angle>
            <max_angle>3.14159</max_angle>
          </horizontal>
        </scan>
        <range>
          <min>0.12</min>
          <max>3.5</max>
          <resolution>0.01</resolution>
        </range>
      </lidar>
    </sensor>
  </gazebo>


  <!-- Init colour -->
  <material name="dark">
    <color rgba="0.2 0.2 0.2 1.0" />
  </material>
  <material name="light_black">
    <color rgba="0.9 0.9 0.9 1.0" />
  </material>


  <!-- Gazebo version -->
  <xacro:arg name="gazebo" default="ignition" />

  <!-- Namespace -->
  <xacro:arg name="namespace" default="" />

  <link name="base_footprint" />

  <joint name="base_joint" type="fixed">
    <parent link="base_footprint" />
    <child link="base_link" />
    <origin xyz="0 0 0.010" rpy="0 0 0" />
  </joint>

  <link name="base_link">
    <visual>
      <origin xyz="-0.064 0 0.0" rpy="0 0 0" />
      <geometry>
        <mesh filename="package://robot/meshes/burger_base.stl"
          scale="0.001 0.001 0.001" />
      </geometry>
      <material name="light_black" />
    </visual>
    <collision>
      <origin xyz="-0.064 0 0.047" rpy="0 0 0" />
      <geometry>
        <box size="0.266 0.266 0.094" />
      </geometry>
    </collision>
    <inertial>
      <origin xyz="0 0 0" rpy="0 0 0" />
      <mass value="1.3729096e+00" />
      <inertia ixx="8.7002718e-03" ixy="-4.7576583e-05" ixz="1.1160499e-04"
        iyy="8.6195418e-03" iyz="-3.5422299e-06"
        izz="1.4612727e-02" />
    </inertial>
  </link>

  <gazebo reference="base_link">
    <xacro:material_light_black />
  </gazebo>

  <joint name="wheel_left_joint" type="continuous">
    <parent link="base_link" />
    <child link="wheel_left_link" />
    <origin xyz="0.0 0.144 0.023" rpy="-1.57 0 0" />
    <axis xyz="0 0 1" />
  </joint>

  <link name="wheel_left_link">
    <visual>
      <origin xyz="0 0 0" rpy="1.57 0 0" />
      <geometry>
        <mesh filename="package://robot/meshes/left_tire.stl"
          scale="0.001 0.001 0.001" />
      </geometry>
      <material name="dark" />
    </visual>
    <collision>
      <origin xyz="0 0 0" rpy="0 0 0" />
      <geometry>
        <cylinder length="0.018" radius="0.033" />
      </geometry>
    </collision>
    <inertial>
      <origin xyz="0 0 0" />
      <mass value="2.8498940e-02" />
      <inertia ixx="1.1175580e-05" ixy="-4.2369783e-11" ixz="-5.9381719e-09"
        iyy="1.1192413e-05" iyz="-1.4400107e-11"
        izz="2.0712558e-05" />
    </inertial>
  </link>

  <gazebo reference="wheel_left_link">
    <xacro:material_darkgray />
  </gazebo>

  <joint name="wheel_right_joint" type="continuous">
    <parent link="base_link" />
    <child link="wheel_right_link" />
    <origin xyz="0.0 -0.144 0.023" rpy="-1.57 0 0" />
    <axis xyz="0 0 1" />
  </joint>

  <link name="wheel_right_link">
    <visual>
      <origin xyz="0 0 0" rpy="1.57 0 0" />
      <geometry>
        <mesh filename="package://robot/meshes/right_tire.stl"
          scale="0.001 0.001 0.001" />
      </geometry>
      <material name="dark" />
    </visual>
    <collision>
      <origin xyz="0 0 0" rpy="0 0 0" />
      <geometry>
        <cylinder length="0.018" radius="0.033" />
      </geometry>
    </collision>
    <inertial>
      <origin xyz="0 0 0" />
      <mass value="2.8498940e-02" />
      <inertia ixx="1.1175580e-05" ixy="-4.2369783e-11" ixz="-5.9381719e-09"
        iyy="1.1192413e-05" iyz="-1.4400107e-11"
        izz="2.0712558e-05" />
    </inertial>
  </link>

  <gazebo reference="wheel_right_link">
    <xacro:material_darkgray />
  </gazebo>

  <joint name="caster_back_right_joint" type="fixed">
    <parent link="base_link" />
    <child link="caster_back_right_link" />
    <origin xyz="-0.177 -0.064 -0.004" rpy="-1.57 0 0" />
  </joint>
  <link name="caster_back_right_link">
    <collision>
      <origin xyz="0 0.001 0" rpy="0 0 0" />
      <geometry>
        <box size="0.030 0.009 0.020" />
      </geometry>
    </collision>
    <inertial>
      <origin xyz="0 0 0" />
      <mass value="0.005" />
      <inertia ixx="0.001" ixy="0.0" ixz="0.0"
        iyy="0.001" iyz="0.0"
        izz="0.001" />
    </inertial>
  </link>

  <joint name="caster_back_left_joint" type="fixed">
    <parent link="base_link" />
    <child link="caster_back_left_link" />
    <origin xyz="-0.177 0.064 -0.004" rpy="-1.57 0 0" />
  </joint>

  <link name="caster_back_left_link">
    <collision>
      <origin xyz="0 0.001 0" rpy="0 0 0" />
      <geometry>
        <box size="0.030 0.009 0.020" />
      </geometry>
    </collision>
    <inertial>
      <origin xyz="0 0 0" />
      <mass value="0.005" />
      <inertia ixx="0.001" ixy="0.0" ixz="0.0"
        iyy="0.001" iyz="0.0"
        izz="0.001" />
    </inertial>
  </link>

  <joint name="imu_joint" type="fixed">
    <parent link="base_link" />
    <child link="imu_link" />
    <origin xyz="0.0 0 0.068" rpy="0 0 0" />
  </joint>

  <link name="imu_link" />

  <joint name="scan_joint" type="fixed">
    <parent link="base_link" />
    <child link="scan_link" />
    <origin xyz="-0.064 0 0.122" rpy="0 0 0" />
  </joint>


  <link name="scan_link">
    <visual>
      <geometry>
        <cylinder radius="0.03" length="0.02"/>
      </geometry>
    </visual>
  </link>

  

  <joint name="camera_joint" type="fixed">
    <origin xyz="0.083 -0.0 0.097" rpy="0 0 0" />
    <parent link="base_link" />
    <child link="camera_link" />
  </joint>

  <link name="camera_link">
    <collision>
      <origin xyz="0.005 0.0 0.013" rpy="0 0 0" />
      <geometry>
        <box size="0.015 0.030 0.027" />
      </geometry>
    </collision>
    <visual>
      <geometry>
        <box size="0.015 0.03 0.027" />
      </geometry>
    </visual>
  </link>

  <joint name="camera_rgb_joint" type="fixed">
    <origin xyz="0.01 0.0 0.0" rpy="0 0 0" />
    <parent link="camera_link" />
    <child link="camera_rgb_frame" />
  </joint>

  <link name="camera_rgb_frame">
    <!-- <visual>
    <origin xyz="0.0 0.0 0.0" rpy="0 1.57 0" />
      <geometry>
        <cylinder radius="0.007" length="0.005" />
      </geometry>
    </visual> -->
  </link>

  <joint name="camera_rgb_optical_joint" type="fixed">
    <origin xyz="0 0 0" rpy="-1.57 0 -1.57" />
    <parent link="camera_rgb_frame" />
    <child link="camera_rgb_optical_frame" />
  </joint>
  <link name="camera_rgb_optical_frame" />


  <gazebo>
    <plugin
      filename="gz-sim-diff-drive-system"
      name="gz::sim::systems::DiffDrive">
      <left_joint>wheel_left_joint</left_joint>
      <right_joint>wheel_right_joint</right_joint>
      <wheel_separation>0.287</wheel_separation>
      <wheel_radius>0.033</wheel_radius>
      <max_linear_acceleration>2</max_linear_acceleration>
      <min_linear_acceleration>-2</min_linear_acceleration>
      <max_angular_acceleration>3</max_angular_acceleration>
      <min_angular_acceleration>-3</min_angular_acceleration>
      <max_linear_velocity>0.5</max_linear_velocity>
      <min_linear_velocity>-0.5</min_linear_velocity>
      <max_angular_velocity>2.0</max_angular_velocity>
      <min_angular_velocity>-2.0</min_angular_velocity>
      <topic>cmd_vel</topic>
      <odom_topic>odom</odom_topic>
      <tf_topic>tf</tf_topic>
      <frame_id>odom</frame_id>
      <child_frame_id>base_footprint</child_frame_id>
      <odom_publish_frequency>30</odom_publish_frequency>
    </plugin>

    <plugin
      filename="gz-sim-joint-state-publisher-system"
      name="gz::sim::systems::JointStatePublisher">
      <joint_name>wheel_left_joint</joint_name>
      <joint_name>wheel_right_joint</joint_name>
      <topic>joint_states</topic>
      <update_rate>30</update_rate>
    </plugin>

  </gazebo>

  <gazebo reference="imu_link">
    <sensor type="imu" name="imu">
      <always_on>true</always_on>
      <update_rate>100</update_rate>
      <topic>imu</topic>
      <imu>
        <angular_velocity>
          <x>
            <noise type="gaussian">
              <mean>0.0</mean>
              <stddev>2e-4</stddev>
            </noise>
          </x>
          <y>
            <noise type="gaussian">
              <mean>0.0</mean>
              <stddev>2e-4</stddev>
            </noise>
          </y>
          <z>
            <noise type="gaussian">
              <mean>0.0</mean>
              <stddev>2e-4</stddev>
            </noise>
          </z>
        </angular_velocity>
        <linear_acceleration>
          <x>
            <noise type="gaussian">
              <mean>0.0</mean>
              <stddev>2e-4</stddev>
            </noise>
          </x>
          <y>
            <noise type="gaussian">
              <mean>0.0</mean>
              <stddev>2e-4</stddev>
            </noise>
          </y>
          <z>
            <noise type="gaussian">
              <mean>0.0</mean>
              <stddev>2e-4</stddev>
            </noise>
          </z>
        </linear_acceleration>
      </imu>
    </sensor>
  </gazebo>

  <gazebo reference="camera_link">
    <sensor name="rgbd_camera" type="rgbd_camera">
      <always_on>1</always_on>
      <camera>
        <horizontal_fov>1.25</horizontal_fov>
        <image>
          <width>640</width>
          <height>480</height>
        </image>
        <clip>
          <near>0.3</near>
          <far>100</far>
        </clip>
        <optical_frame_id>camera_rgb_optical_frame</optical_frame_id>
      </camera>
      <update_rate>10</update_rate>
      <visualize>true</visualize>
      <topic>rgbd_camera</topic>
    </sensor>
    <xacro:material_darkgray />
  </gazebo>

</robot>