<?xml version="1.0"?>
<robot name="my_robot" xmlns:xacro="http://www.ros.org/wiki/xacro">
    
    <material name="blue">
        <color rgba="0 0 0.5 1" />
    </material>

    <material name="grey">
        <color rgba="0.5 0.5 0.5 1" />
    </material>

    <material name="orange">
        <color rgba="1.0 0.5 0 1" />
    </material>

    <material name="yellow">
        <color rgba="1.0 1.0 0 1" />
    </material>

    <xacro:macro name="box_inertia" params="m x y z o_xyz o_rpy">
        <inertial>
            <mass value="${m}" />
            <origin xyz="${o_xyz}" rpy="${o_rpy}" />
            <inertia ixx="${(m/12) * (y*y + z*z)}" ixy="0" ixz="0"
                     iyy="${(m/12) * (x*x + z*z)}" iyz="0"
                     izz="${(m/12) * (x*x + y*y)}" />
        </inertial>
    </xacro:macro>

    <xacro:macro name="cylinder_inertia" params="m r l o_xyz o_rpy">
        <inertial>
            <mass value="${m}" />
            <origin xyz="${o_xyz}" rpy="${o_rpy}" />
            <inertia ixx="${(m/12) * (3*r*r + l*l)}" ixy="0" ixz="0"
                     iyy="${(m/12) * (3*r*r + l*l)}" iyz="0"
                     izz="${(m/2) * (r*r)}" />
        </inertial>
    </xacro:macro>

    <xacro:macro name="sphere_inertia" params="m r o_xyz o_rpy">
        <inertial>
            <mass value="${m}" />
            <origin xyz="${o_xyz}" rpy="${o_rpy}" />
            <inertia ixx="${(2/5) * m * r * r}" ixy="0" ixz="0"
                     iyy="${(2/5) * m * r * r}" iyz="0"
                     izz="${(2/5) * m * r * r}" />
        </inertial>
    </xacro:macro>


    <xacro:property name="base_length" value="0.6" />
    <xacro:property name="base_width" value="0.4" />
    <xacro:property name="base_height" value="0.2" />
    <xacro:property name="wheel_radius" value="0.1" />
    <xacro:property name="wheel_length" value="0.05" />

    <link name="base_footprint" />

    <link name="base_link">
        <visual>
            <geometry>
                <box size="${base_length} ${base_width} ${base_height}" />
            </geometry>
            <origin xyz="0 0 ${base_height / 2.0}" rpy="0 0 0" />
            <material name="blue" />
        </visual>
        <collision>
            <geometry>
                <box size="${base_length} ${base_width} ${base_height}" />
            </geometry>
            <origin xyz="0 0 ${base_height / 2.0}" rpy="0 0 0" />
        </collision>
        <xacro:box_inertia m="5.0" x="${base_length}" y="${base_width}" z="${base_height}"
                           o_xyz="0 0 ${base_height / 2.0}" o_rpy="0 0 0" />
    </link>

    <xacro:macro name="wheel_link" params="prefix">
        <link name="${prefix}_wheel_link">
            <visual>
                <geometry>
                    <cylinder radius="${wheel_radius}" length="${wheel_length}" />
                </geometry>
                <origin xyz="0 0 0" rpy="${pi / 2.0} 0 0" />
                <material name="grey" />
            </visual>
            <collision>
                <geometry>
                    <sphere radius="${wheel_radius}" />
                </geometry>
                <origin xyz="0 0 0" rpy="0 0 0" />
            </collision>
            <xacro:cylinder_inertia m="1.0" r="${wheel_radius}" l="${wheel_length}"
                                    o_xyz="0 0 0" o_rpy="${pi / 2.0} 0 0" />
        </link>
    </xacro:macro>

    <xacro:wheel_link prefix="right" />
    <xacro:wheel_link prefix="left" />

    <link name="caster_wheel_link">
        <visual>
            <geometry>
                <sphere radius="${wheel_radius / 2.0}" />
            </geometry>
            <origin xyz="0 0 0" rpy="0 0 0" />
            <material name="grey" />
        </visual>
        <collision>
            <geometry>
                <sphere radius="${wheel_radius / 2.0}" />
            </geometry>
            <origin xyz="0 0 0" rpy="0 0 0" />
        </collision>
        <xacro:sphere_inertia m="0.5" r="${wheel_radius / 2.0}"
                              o_xyz="0 0 0" o_rpy="0 0 0" />
    </link>

    <joint name="base_joint" type="fixed">
        <parent link="base_footprint" />
        <child link="base_link" />
        <origin xyz="0 0 ${wheel_radius}" rpy="0 0 0"/>
    </joint>

    <joint name="base_right_wheel_joint" type="continuous">
        <parent link="base_link" />
        <child link="right_wheel_link" />
        <origin xyz="${-base_length / 4.0} ${-(base_width + wheel_length) / 2.0} 0" rpy="0 0 0" />
        <axis xyz="0 1 0" />
    </joint>

    <joint name="base_left_wheel_joint" type="continuous">
        <parent link="base_link" />
        <child link="left_wheel_link" />
        <origin xyz="${-base_length / 4.0} ${(base_width + wheel_length) / 2.0} 0" rpy="0 0 0" />
        <axis xyz="0 1 0" />
    </joint>

    <joint name="base_caster_wheel_joint" type="fixed">
        <parent link="base_link" />
        <child link="caster_wheel_link" />
        <origin xyz="${base_length / 3.0} 0 ${-wheel_radius / 2.0}" rpy="0 0 0" />
    </joint>

    <gazebo reference="caster_wheel_link">
        <mu1 value="0.1" />
        <mu2 value="0.1" />
    </gazebo>

    <gazebo>
        <plugin 
            filename="gz-sim-diff-drive-system" 
            name="gz::sim::systems::DiffDrive">
            <left_joint>base_left_wheel_joint</left_joint>
            <right_joint>base_right_wheel_joint</right_joint>
            <wheel_separation>0.45</wheel_separation>
            <wheel_radius>0.1</wheel_radius>
            <frame_id>odom</frame_id>
            <child_frame_id>base_footprint</child_frame_id>
            
            <odom_topic>odom</odom_topic>
            <publish_odom_tf>true</publish_odom_tf> 
        </plugin>
    </gazebo>

    <gazebo>
        <plugin 
            filename="gz-sim-joint-state-publisher-system" 
            name="gz::sim::systems::JointStatePublisher">
            <joint_name>base_left_wheel_joint</joint_name>
            <joint_name>base_right_wheel_joint</joint_name>
        </plugin>
    </gazebo>

    <xacro:property name="camera_length" value="0.01" />
    <xacro:property name="camera_width" value="0.1" />
    <xacro:property name="camera_height" value="0.05" />

    <link name="camera_link">
        <visual>
            <geometry>
                <box size="${camera_length} ${camera_width} ${camera_height}" />
            </geometry>
            <material name="grey" />
        </visual>
        <collision>
            <geometry>
                <box size="${camera_length} ${camera_width} ${camera_height}" />
            </geometry>
        </collision>
        <xacro:box_inertia m="0.1" x="${camera_length}" y="${camera_width}" z="${camera_height}"
                           o_xyz="0 0 0" o_rpy="0 0 0" />
    </link>

    <joint name="base_camera_joint" type="fixed">
        <parent link="base_link" />
        <child link="camera_link" />
        <origin xyz="${(base_length + camera_length) / 2.0} 0 ${base_height / 2.0}" rpy="0 0 0" />
    </joint>

    <link name="camera_link_optical" />

    <joint name="camera_optical_joint" type="fixed">
        <origin xyz="0 0 0" rpy="${-pi/2} 0 ${-pi/2}"/>
        <parent link="camera_link"/>
        <child link="camera_link_optical"/>
    </joint>

    <gazebo reference="camera_link">
        <sensor name="camera" type="camera">
            <camera>
                <horizontal_fov>1.3962634</horizontal_fov>
                <image>
                    <width>640</width>
                    <height>480</height>
                    <format>R8G8B8</format>
                </image>
                <clip>
                    <near>0.1</near>
                    <far>15</far>
                </clip>
                <noise>
                    <type>gaussian</type>
                    <mean>0.0</mean>
                    <stddev>0.007</stddev>
                </noise>
                <optical_frame_id>camera_link_optical</optical_frame_id>
                <camera_info_topic>camera/camera_info</camera_info_topic>
            </camera>
            <always_on>1</always_on>
            <update_rate>20</update_rate>
            <visualize>true</visualize>
            <topic>camera/image_raw</topic>            
        </sensor>
    </gazebo>

        <!-- ================= LIDAR LINK ================= -->
    <link name="lidar_link">
        <inertial>
            <mass value="0.1"/>
            <origin xyz="0 0 0" rpy="0 0 0"/>
            <inertia ixx="1e-4" ixy="0" ixz="0"
                     iyy="1e-4" iyz="0"
                     izz="1e-4"/>
        </inertial>

        <visual>
            <origin xyz="0 0 0" rpy="0 0 0"/>
            <geometry>
                <cylinder radius="0.03" length="0.04"/>
            </geometry>
        </visual>

        <collision>
            <origin xyz="0 0 0" rpy="0 0 0"/>
            <geometry>
                <cylinder radius="0.03" length="0.04"/>
            </geometry>
        </collision>
    </link>

    <!-- ================= LIDAR JOINT ================= -->
    <joint name="lidar_joint" type="fixed">
        <parent link="base_link"/>
        <child link="lidar_link"/>
        <!-- Adjust mounting position if needed -->
        <origin xyz="0.15 0 0.20" rpy="0 0 0"/>
    </joint>

    <!-- ================= GAZEBO HARMONIC SENSOR ================= -->
    <gazebo reference="lidar_link">
        <sensor name="lidar_sensor" type="gpu_lidar">
            <topic>scan</topic>
            <update_rate>10</update_rate>
            <always_on>true</always_on>
            <visualize>false</visualize>

            <ray>
                <scan>
                    <horizontal>
                        <samples>720</samples>
                        <resolution>1</resolution>
                        <min_angle>-3.14159</min_angle>
                        <max_angle>3.14159</max_angle>
                    </horizontal>
                    <vertical>
                        <samples>1</samples>
                        <resolution>1</resolution>
                        <min_angle>0</min_angle>
                        <max_angle>0</max_angle>
                    </vertical>
                </scan>

                <range>
                    <min>0.2</min>
                    <max>30</max>
                    <resolution>0.013</resolution>
                </range>
            </ray>

            <gz_frame_id>lidar_link</gz_frame_id>
        </sensor>
    </gazebo>

</robot>